[2024-11-12T12:54:30.859+0000] {local_task_job_runner.py:123} INFO - ::group::Pre task execution logs
[2024-11-12T12:54:30.894+0000] {taskinstance.py:2613} INFO - Dependencies all met for dep_context=non-requeueable deps ti=<TaskInstance: docker_build_and_run.docker_build_image manual__2024-11-12T12:54:27.182492+00:00 [queued]>
[2024-11-12T12:54:30.912+0000] {taskinstance.py:2613} INFO - Dependencies all met for dep_context=requeueable deps ti=<TaskInstance: docker_build_and_run.docker_build_image manual__2024-11-12T12:54:27.182492+00:00 [queued]>
[2024-11-12T12:54:30.913+0000] {taskinstance.py:2866} INFO - Starting attempt 1 of 1
[2024-11-12T12:54:30.929+0000] {taskinstance.py:2889} INFO - Executing <Task(DockerOperator): docker_build_image> on 2024-11-12 12:54:27.182492+00:00
[2024-11-12T12:54:30.945+0000] {logging_mixin.py:190} WARNING - /home/airflow/.local/lib/python3.12/site-packages/airflow/task/task_runner/standard_task_runner.py:70 DeprecationWarning: This process (pid=199) is multi-threaded, use of fork() may lead to deadlocks in the child.
[2024-11-12T12:54:30.946+0000] {standard_task_runner.py:72} INFO - Started process 200 to run task
[2024-11-12T12:54:30.946+0000] {standard_task_runner.py:104} INFO - Running: ['airflow', 'tasks', 'run', 'docker_build_and_run', 'docker_build_image', 'manual__2024-11-12T12:54:27.182492+00:00', '--job-id', '2', '--raw', '--subdir', 'DAGS_FOLDER/test_main.py', '--cfg-path', '/tmp/tmp_ogo_cij']
[2024-11-12T12:54:30.947+0000] {standard_task_runner.py:105} INFO - Job 2: Subtask docker_build_image
[2024-11-12T12:54:30.964+0000] {logging_mixin.py:190} WARNING - /home/airflow/.local/lib/python3.12/site-packages/airflow/settings.py:209 DeprecationWarning: The sql_alchemy_conn option in [core] has been moved to the sql_alchemy_conn option in [database] - the old setting has been used, but please update your config.
[2024-11-12T12:54:31.000+0000] {task_command.py:467} INFO - Running <TaskInstance: docker_build_and_run.docker_build_image manual__2024-11-12T12:54:27.182492+00:00 [running]> on host 6cd0521d5bd9
[2024-11-12T12:54:31.146+0000] {taskinstance.py:3132} INFO - Exporting env vars: AIRFLOW_CTX_DAG_OWNER='airflow' AIRFLOW_CTX_DAG_ID='docker_build_and_run' AIRFLOW_CTX_TASK_ID='docker_build_image' AIRFLOW_CTX_EXECUTION_DATE='2024-11-12T12:54:27.182492+00:00' AIRFLOW_CTX_TRY_NUMBER='1' AIRFLOW_CTX_DAG_RUN_ID='manual__2024-11-12T12:54:27.182492+00:00'
[2024-11-12T12:54:31.149+0000] {taskinstance.py:731} INFO - ::endgroup::
[2024-11-12T12:54:31.289+0000] {docker.py:157} ERROR - Failed to establish connection to Docker host tcp://localhost:2375: Error while fetching server API version: HTTPConnectionPool(host='localhost', port=2375): Max retries exceeded with url: /version (Caused by NewConnectionError('<urllib3.connection.HTTPConnection object at 0x7fd3cf637b60>: Failed to establish a new connection: [Errno 111] Connection refused'))
[2024-11-12T12:54:31.307+0000] {taskinstance.py:3311} ERROR - Task failed with exception
Traceback (most recent call last):
  File "/home/airflow/.local/lib/python3.12/site-packages/airflow/models/taskinstance.py", line 767, in _execute_task
    result = _execute_callable(context=context, **execute_callable_kwargs)
             ^^^^^^^^^^^^^^^^^^^^^^^^^^^^^^^^^^^^^^^^^^^^^^^^^^^^^^^^^^^^^
  File "/home/airflow/.local/lib/python3.12/site-packages/airflow/models/taskinstance.py", line 733, in _execute_callable
    return ExecutionCallableRunner(
           ^^^^^^^^^^^^^^^^^^^^^^^^
  File "/home/airflow/.local/lib/python3.12/site-packages/airflow/utils/operator_helpers.py", line 252, in run
    return self.func(*args, **kwargs)
           ^^^^^^^^^^^^^^^^^^^^^^^^^^
  File "/home/airflow/.local/lib/python3.12/site-packages/airflow/models/baseoperator.py", line 417, in wrapper
    return func(self, *args, **kwargs)
           ^^^^^^^^^^^^^^^^^^^^^^^^^^^
  File "/home/airflow/.local/lib/python3.12/site-packages/airflow/providers/docker/operators/docker.py", line 494, in execute
    if self.force_pull or not self.cli.images(name=self.image):
                              ^^^^^^^^
  File "/home/airflow/.local/lib/python3.12/site-packages/airflow/providers/docker/operators/docker.py", line 363, in cli
    return self.hook.api_client
           ^^^^^^^^^^^^^^^^^^^^
  File "/usr/local/lib/python3.12/functools.py", line 993, in __get__
    val = self.func(instance)
          ^^^^^^^^^^^^^^^^^^^
  File "/home/airflow/.local/lib/python3.12/site-packages/airflow/providers/docker/hooks/docker.py", line 161, in api_client
    raise AirflowException("Failed to establish connection to any given Docker hosts.")
airflow.exceptions.AirflowException: Failed to establish connection to any given Docker hosts.
[2024-11-12T12:54:31.324+0000] {taskinstance.py:1225} INFO - Marking task as FAILED. dag_id=docker_build_and_run, task_id=docker_build_image, run_id=manual__2024-11-12T12:54:27.182492+00:00, execution_date=20241112T125427, start_date=20241112T125430, end_date=20241112T125431
[2024-11-12T12:54:31.341+0000] {taskinstance.py:340} INFO - ::group::Post task execution logs
[2024-11-12T12:54:31.343+0000] {standard_task_runner.py:124} ERROR - Failed to execute job 2 for task docker_build_image (Failed to establish connection to any given Docker hosts.; 200)
Traceback (most recent call last):
  File "/home/airflow/.local/lib/python3.12/site-packages/airflow/task/task_runner/standard_task_runner.py", line 117, in _start_by_fork
    ret = args.func(args, dag=self.dag)
          ^^^^^^^^^^^^^^^^^^^^^^^^^^^^^
  File "/home/airflow/.local/lib/python3.12/site-packages/airflow/cli/cli_config.py", line 49, in command
    return func(*args, **kwargs)
           ^^^^^^^^^^^^^^^^^^^^^
  File "/home/airflow/.local/lib/python3.12/site-packages/airflow/utils/cli.py", line 116, in wrapper
    return f(*args, **kwargs)
           ^^^^^^^^^^^^^^^^^^
  File "/home/airflow/.local/lib/python3.12/site-packages/airflow/cli/commands/task_command.py", line 483, in task_run
    task_return_code = _run_task_by_selected_method(args, _dag, ti)
                       ^^^^^^^^^^^^^^^^^^^^^^^^^^^^^^^^^^^^^^^^^^^^
  File "/home/airflow/.local/lib/python3.12/site-packages/airflow/cli/commands/task_command.py", line 256, in _run_task_by_selected_method
    return _run_raw_task(args, ti)
           ^^^^^^^^^^^^^^^^^^^^^^^
  File "/home/airflow/.local/lib/python3.12/site-packages/airflow/cli/commands/task_command.py", line 341, in _run_raw_task
    return ti._run_raw_task(
           ^^^^^^^^^^^^^^^^^
  File "/home/airflow/.local/lib/python3.12/site-packages/airflow/utils/session.py", line 97, in wrapper
    return func(*args, session=session, **kwargs)
           ^^^^^^^^^^^^^^^^^^^^^^^^^^^^^^^^^^^^^^
  File "/home/airflow/.local/lib/python3.12/site-packages/airflow/models/taskinstance.py", line 3005, in _run_raw_task
    return _run_raw_task(
           ^^^^^^^^^^^^^^
  File "/home/airflow/.local/lib/python3.12/site-packages/airflow/models/taskinstance.py", line 273, in _run_raw_task
    TaskInstance._execute_task_with_callbacks(
  File "/home/airflow/.local/lib/python3.12/site-packages/airflow/models/taskinstance.py", line 3159, in _execute_task_with_callbacks
    result = self._execute_task(context, task_orig)
             ^^^^^^^^^^^^^^^^^^^^^^^^^^^^^^^^^^^^^^
  File "/home/airflow/.local/lib/python3.12/site-packages/airflow/models/taskinstance.py", line 3183, in _execute_task
    return _execute_task(self, context, task_orig)
           ^^^^^^^^^^^^^^^^^^^^^^^^^^^^^^^^^^^^^^^
  File "/home/airflow/.local/lib/python3.12/site-packages/airflow/models/taskinstance.py", line 767, in _execute_task
    result = _execute_callable(context=context, **execute_callable_kwargs)
             ^^^^^^^^^^^^^^^^^^^^^^^^^^^^^^^^^^^^^^^^^^^^^^^^^^^^^^^^^^^^^
  File "/home/airflow/.local/lib/python3.12/site-packages/airflow/models/taskinstance.py", line 733, in _execute_callable
    return ExecutionCallableRunner(
           ^^^^^^^^^^^^^^^^^^^^^^^^
  File "/home/airflow/.local/lib/python3.12/site-packages/airflow/utils/operator_helpers.py", line 252, in run
    return self.func(*args, **kwargs)
           ^^^^^^^^^^^^^^^^^^^^^^^^^^
  File "/home/airflow/.local/lib/python3.12/site-packages/airflow/models/baseoperator.py", line 417, in wrapper
    return func(self, *args, **kwargs)
           ^^^^^^^^^^^^^^^^^^^^^^^^^^^
  File "/home/airflow/.local/lib/python3.12/site-packages/airflow/providers/docker/operators/docker.py", line 494, in execute
    if self.force_pull or not self.cli.images(name=self.image):
                              ^^^^^^^^
  File "/home/airflow/.local/lib/python3.12/site-packages/airflow/providers/docker/operators/docker.py", line 363, in cli
    return self.hook.api_client
           ^^^^^^^^^^^^^^^^^^^^
  File "/usr/local/lib/python3.12/functools.py", line 993, in __get__
    val = self.func(instance)
          ^^^^^^^^^^^^^^^^^^^
  File "/home/airflow/.local/lib/python3.12/site-packages/airflow/providers/docker/hooks/docker.py", line 161, in api_client
    raise AirflowException("Failed to establish connection to any given Docker hosts.")
airflow.exceptions.AirflowException: Failed to establish connection to any given Docker hosts.
[2024-11-12T12:54:31.383+0000] {local_task_job_runner.py:266} INFO - Task exited with return code 1
[2024-11-12T12:54:31.410+0000] {taskinstance.py:3895} INFO - 0 downstream tasks scheduled from follow-on schedule check
[2024-11-12T12:54:31.415+0000] {local_task_job_runner.py:245} INFO - ::endgroup::
