[2024-11-12T13:33:24.189+0000] {local_task_job_runner.py:123} INFO - ::group::Pre task execution logs
[2024-11-12T13:33:24.220+0000] {taskinstance.py:2613} INFO - Dependencies all met for dep_context=non-requeueable deps ti=<TaskInstance: docker_connection_test.docker_connection_test manual__2024-11-12T13:33:22.941685+00:00 [queued]>
[2024-11-12T13:33:24.232+0000] {taskinstance.py:2613} INFO - Dependencies all met for dep_context=requeueable deps ti=<TaskInstance: docker_connection_test.docker_connection_test manual__2024-11-12T13:33:22.941685+00:00 [queued]>
[2024-11-12T13:33:24.233+0000] {taskinstance.py:2866} INFO - Starting attempt 1 of 1
[2024-11-12T13:33:24.251+0000] {taskinstance.py:2889} INFO - Executing <Task(DockerOperator): docker_connection_test> on 2024-11-12 13:33:22.941685+00:00
[2024-11-12T13:33:24.267+0000] {logging_mixin.py:190} WARNING - /home/airflow/.local/lib/python3.12/site-packages/airflow/task/task_runner/standard_task_runner.py:70 DeprecationWarning: This process (pid=199) is multi-threaded, use of fork() may lead to deadlocks in the child.
[2024-11-12T13:33:24.266+0000] {standard_task_runner.py:104} INFO - Running: ['airflow', 'tasks', 'run', 'docker_connection_test', 'docker_connection_test', 'manual__2024-11-12T13:33:22.941685+00:00', '--job-id', '2', '--raw', '--subdir', 'DAGS_FOLDER/test_main.py', '--cfg-path', '/tmp/tmpnigbvenx']
[2024-11-12T13:33:24.270+0000] {standard_task_runner.py:72} INFO - Started process 200 to run task
[2024-11-12T13:33:24.271+0000] {standard_task_runner.py:105} INFO - Job 2: Subtask docker_connection_test
[2024-11-12T13:33:24.289+0000] {logging_mixin.py:190} WARNING - /home/airflow/.local/lib/python3.12/site-packages/airflow/settings.py:209 DeprecationWarning: The sql_alchemy_conn option in [core] has been moved to the sql_alchemy_conn option in [database] - the old setting has been used, but please update your config.
[2024-11-12T13:33:24.326+0000] {task_command.py:467} INFO - Running <TaskInstance: docker_connection_test.docker_connection_test manual__2024-11-12T13:33:22.941685+00:00 [running]> on host ef80f2d74fd5
[2024-11-12T13:33:24.421+0000] {taskinstance.py:3132} INFO - Exporting env vars: AIRFLOW_CTX_DAG_OWNER='airflow' AIRFLOW_CTX_DAG_ID='docker_connection_test' AIRFLOW_CTX_TASK_ID='docker_connection_test' AIRFLOW_CTX_EXECUTION_DATE='2024-11-12T13:33:22.941685+00:00' AIRFLOW_CTX_TRY_NUMBER='1' AIRFLOW_CTX_DAG_RUN_ID='manual__2024-11-12T13:33:22.941685+00:00'
[2024-11-12T13:33:24.422+0000] {taskinstance.py:731} INFO - ::endgroup::
[2024-11-12T13:33:24.624+0000] {docker.py:367} INFO - Starting docker container from image docker:latest
[2024-11-12T13:33:35.860+0000] {docker.py:438} INFO - ERROR: error during connect: Get "http://docker:2375/v1.47/info": dial tcp: lookup docker on 192.168.65.7:53: no such host
[2024-11-12T13:33:35.862+0000] {docker.py:438} INFO - errors pretty printing info
[2024-11-12T13:33:35.872+0000] {docker.py:438} INFO - Client:
[2024-11-12T13:33:35.875+0000] {docker.py:438} INFO -  Version:    27.3.1
[2024-11-12T13:33:35.881+0000] {docker.py:438} INFO -  Context:    default
[2024-11-12T13:33:35.882+0000] {docker.py:438} INFO -  Debug Mode: false
[2024-11-12T13:33:35.882+0000] {docker.py:438} INFO -  Plugins:
[2024-11-12T13:33:35.883+0000] {docker.py:438} INFO -   buildx: Docker Buildx (Docker Inc.)
[2024-11-12T13:33:35.890+0000] {docker.py:438} INFO -     Version:  v0.18.0
[2024-11-12T13:33:35.891+0000] {docker.py:438} INFO -     Path:     /usr/local/libexec/docker/cli-plugins/docker-buildx
[2024-11-12T13:33:35.893+0000] {docker.py:438} INFO -   compose: Docker Compose (Docker Inc.)
[2024-11-12T13:33:35.894+0000] {docker.py:438} INFO -     Version:  v2.30.3
[2024-11-12T13:33:35.894+0000] {docker.py:438} INFO -     Path:     /usr/local/libexec/docker/cli-plugins/docker-compose
[2024-11-12T13:33:35.895+0000] {docker.py:438} INFO - 
[2024-11-12T13:33:35.898+0000] {docker.py:438} INFO - Server:
[2024-11-12T13:33:36.231+0000] {taskinstance.py:3311} ERROR - Task failed with exception
Traceback (most recent call last):
  File "/home/airflow/.local/lib/python3.12/site-packages/airflow/models/taskinstance.py", line 767, in _execute_task
    result = _execute_callable(context=context, **execute_callable_kwargs)
             ^^^^^^^^^^^^^^^^^^^^^^^^^^^^^^^^^^^^^^^^^^^^^^^^^^^^^^^^^^^^^
  File "/home/airflow/.local/lib/python3.12/site-packages/airflow/models/taskinstance.py", line 733, in _execute_callable
    return ExecutionCallableRunner(
           ^^^^^^^^^^^^^^^^^^^^^^^^
  File "/home/airflow/.local/lib/python3.12/site-packages/airflow/utils/operator_helpers.py", line 252, in run
    return self.func(*args, **kwargs)
           ^^^^^^^^^^^^^^^^^^^^^^^^^^
  File "/home/airflow/.local/lib/python3.12/site-packages/airflow/models/baseoperator.py", line 417, in wrapper
    return func(self, *args, **kwargs)
           ^^^^^^^^^^^^^^^^^^^^^^^^^^^
  File "/home/airflow/.local/lib/python3.12/site-packages/airflow/providers/docker/operators/docker.py", line 512, in execute
    return self._run_image()
           ^^^^^^^^^^^^^^^^^
  File "/home/airflow/.local/lib/python3.12/site-packages/airflow/providers/docker/operators/docker.py", line 384, in _run_image
    return self._run_image_with_mounts(self.mounts, add_tmp_variable=False)
           ^^^^^^^^^^^^^^^^^^^^^^^^^^^^^^^^^^^^^^^^^^^^^^^^^^^^^^^^^^^^^^^^
  File "/home/airflow/.local/lib/python3.12/site-packages/airflow/providers/docker/operators/docker.py", line 446, in _run_image_with_mounts
    raise DockerContainerFailedException(f"Docker container failed: {result!r}", logs=log_lines)
airflow.providers.docker.exceptions.DockerContainerFailedException: Docker container failed: {'StatusCode': 1}
[2024-11-12T13:33:36.240+0000] {taskinstance.py:1225} INFO - Marking task as FAILED. dag_id=docker_connection_test, task_id=docker_connection_test, run_id=manual__2024-11-12T13:33:22.941685+00:00, execution_date=20241112T133322, start_date=20241112T133324, end_date=20241112T133336
[2024-11-12T13:33:36.254+0000] {taskinstance.py:340} INFO - ::group::Post task execution logs
[2024-11-12T13:33:36.255+0000] {standard_task_runner.py:124} ERROR - Failed to execute job 2 for task docker_connection_test (Docker container failed: {'StatusCode': 1}; 200)
Traceback (most recent call last):
  File "/home/airflow/.local/lib/python3.12/site-packages/airflow/task/task_runner/standard_task_runner.py", line 117, in _start_by_fork
    ret = args.func(args, dag=self.dag)
          ^^^^^^^^^^^^^^^^^^^^^^^^^^^^^
  File "/home/airflow/.local/lib/python3.12/site-packages/airflow/cli/cli_config.py", line 49, in command
    return func(*args, **kwargs)
           ^^^^^^^^^^^^^^^^^^^^^
  File "/home/airflow/.local/lib/python3.12/site-packages/airflow/utils/cli.py", line 116, in wrapper
    return f(*args, **kwargs)
           ^^^^^^^^^^^^^^^^^^
  File "/home/airflow/.local/lib/python3.12/site-packages/airflow/cli/commands/task_command.py", line 483, in task_run
    task_return_code = _run_task_by_selected_method(args, _dag, ti)
                       ^^^^^^^^^^^^^^^^^^^^^^^^^^^^^^^^^^^^^^^^^^^^
  File "/home/airflow/.local/lib/python3.12/site-packages/airflow/cli/commands/task_command.py", line 256, in _run_task_by_selected_method
    return _run_raw_task(args, ti)
           ^^^^^^^^^^^^^^^^^^^^^^^
  File "/home/airflow/.local/lib/python3.12/site-packages/airflow/cli/commands/task_command.py", line 341, in _run_raw_task
    return ti._run_raw_task(
           ^^^^^^^^^^^^^^^^^
  File "/home/airflow/.local/lib/python3.12/site-packages/airflow/utils/session.py", line 97, in wrapper
    return func(*args, session=session, **kwargs)
           ^^^^^^^^^^^^^^^^^^^^^^^^^^^^^^^^^^^^^^
  File "/home/airflow/.local/lib/python3.12/site-packages/airflow/models/taskinstance.py", line 3005, in _run_raw_task
    return _run_raw_task(
           ^^^^^^^^^^^^^^
  File "/home/airflow/.local/lib/python3.12/site-packages/airflow/models/taskinstance.py", line 273, in _run_raw_task
    TaskInstance._execute_task_with_callbacks(
  File "/home/airflow/.local/lib/python3.12/site-packages/airflow/models/taskinstance.py", line 3159, in _execute_task_with_callbacks
    result = self._execute_task(context, task_orig)
             ^^^^^^^^^^^^^^^^^^^^^^^^^^^^^^^^^^^^^^
  File "/home/airflow/.local/lib/python3.12/site-packages/airflow/models/taskinstance.py", line 3183, in _execute_task
    return _execute_task(self, context, task_orig)
           ^^^^^^^^^^^^^^^^^^^^^^^^^^^^^^^^^^^^^^^
  File "/home/airflow/.local/lib/python3.12/site-packages/airflow/models/taskinstance.py", line 767, in _execute_task
    result = _execute_callable(context=context, **execute_callable_kwargs)
             ^^^^^^^^^^^^^^^^^^^^^^^^^^^^^^^^^^^^^^^^^^^^^^^^^^^^^^^^^^^^^
  File "/home/airflow/.local/lib/python3.12/site-packages/airflow/models/taskinstance.py", line 733, in _execute_callable
    return ExecutionCallableRunner(
           ^^^^^^^^^^^^^^^^^^^^^^^^
  File "/home/airflow/.local/lib/python3.12/site-packages/airflow/utils/operator_helpers.py", line 252, in run
    return self.func(*args, **kwargs)
           ^^^^^^^^^^^^^^^^^^^^^^^^^^
  File "/home/airflow/.local/lib/python3.12/site-packages/airflow/models/baseoperator.py", line 417, in wrapper
    return func(self, *args, **kwargs)
           ^^^^^^^^^^^^^^^^^^^^^^^^^^^
  File "/home/airflow/.local/lib/python3.12/site-packages/airflow/providers/docker/operators/docker.py", line 512, in execute
    return self._run_image()
           ^^^^^^^^^^^^^^^^^
  File "/home/airflow/.local/lib/python3.12/site-packages/airflow/providers/docker/operators/docker.py", line 384, in _run_image
    return self._run_image_with_mounts(self.mounts, add_tmp_variable=False)
           ^^^^^^^^^^^^^^^^^^^^^^^^^^^^^^^^^^^^^^^^^^^^^^^^^^^^^^^^^^^^^^^^
  File "/home/airflow/.local/lib/python3.12/site-packages/airflow/providers/docker/operators/docker.py", line 446, in _run_image_with_mounts
    raise DockerContainerFailedException(f"Docker container failed: {result!r}", logs=log_lines)
airflow.providers.docker.exceptions.DockerContainerFailedException: Docker container failed: {'StatusCode': 1}
[2024-11-12T13:33:36.292+0000] {local_task_job_runner.py:266} INFO - Task exited with return code 1
[2024-11-12T13:33:36.310+0000] {taskinstance.py:3895} INFO - 0 downstream tasks scheduled from follow-on schedule check
[2024-11-12T13:33:36.312+0000] {local_task_job_runner.py:245} INFO - ::endgroup::
