[2024-11-12T15:17:17.575+0000] {local_task_job_runner.py:123} INFO - ::group::Pre task execution logs
[2024-11-12T15:17:17.608+0000] {taskinstance.py:2613} INFO - Dependencies all met for dep_context=non-requeueable deps ti=<TaskInstance: etl_kimdong_dag.mongodb_to_kafka manual__2024-11-12T15:17:16.335645+00:00 [queued]>
[2024-11-12T15:17:17.623+0000] {taskinstance.py:2613} INFO - Dependencies all met for dep_context=requeueable deps ti=<TaskInstance: etl_kimdong_dag.mongodb_to_kafka manual__2024-11-12T15:17:16.335645+00:00 [queued]>
[2024-11-12T15:17:17.624+0000] {taskinstance.py:2866} INFO - Starting attempt 1 of 1
[2024-11-12T15:17:17.642+0000] {taskinstance.py:2889} INFO - Executing <Task(BashOperator): mongodb_to_kafka> on 2024-11-12 15:17:16.335645+00:00
[2024-11-12T15:17:17.653+0000] {logging_mixin.py:190} WARNING - /home/airflow/.local/lib/python3.12/site-packages/airflow/task/task_runner/standard_task_runner.py:70 DeprecationWarning: This process (pid=199) is multi-threaded, use of fork() may lead to deadlocks in the child.
[2024-11-12T15:17:17.653+0000] {standard_task_runner.py:104} INFO - Running: ['airflow', 'tasks', 'run', 'etl_kimdong_dag', 'mongodb_to_kafka', 'manual__2024-11-12T15:17:16.335645+00:00', '--job-id', '2', '--raw', '--subdir', 'DAGS_FOLDER/test_main.py', '--cfg-path', '/tmp/tmpypryxff4']
[2024-11-12T15:17:17.656+0000] {standard_task_runner.py:72} INFO - Started process 200 to run task
[2024-11-12T15:17:17.657+0000] {standard_task_runner.py:105} INFO - Job 2: Subtask mongodb_to_kafka
[2024-11-12T15:17:17.674+0000] {logging_mixin.py:190} WARNING - /home/airflow/.local/lib/python3.12/site-packages/airflow/settings.py:209 DeprecationWarning: The sql_alchemy_conn option in [core] has been moved to the sql_alchemy_conn option in [database] - the old setting has been used, but please update your config.
[2024-11-12T15:17:17.712+0000] {task_command.py:467} INFO - Running <TaskInstance: etl_kimdong_dag.mongodb_to_kafka manual__2024-11-12T15:17:16.335645+00:00 [running]> on host 0b2758a4950e
[2024-11-12T15:17:17.802+0000] {taskinstance.py:3132} INFO - Exporting env vars: AIRFLOW_CTX_DAG_OWNER='airflow' AIRFLOW_CTX_DAG_ID='etl_kimdong_dag' AIRFLOW_CTX_TASK_ID='mongodb_to_kafka' AIRFLOW_CTX_EXECUTION_DATE='2024-11-12T15:17:16.335645+00:00' AIRFLOW_CTX_TRY_NUMBER='1' AIRFLOW_CTX_DAG_RUN_ID='manual__2024-11-12T15:17:16.335645+00:00'
[2024-11-12T15:17:17.803+0000] {taskinstance.py:731} INFO - ::endgroup::
[2024-11-12T15:17:17.853+0000] {subprocess.py:78} INFO - Tmp dir root location: /tmp
[2024-11-12T15:17:17.855+0000] {subprocess.py:88} INFO - Running command: ['/usr/bin/bash', '-c', 'docker exec -it mymongodb_container python web/Connection_Postgresql/main_MongoDBConnectKafka.py']
[2024-11-12T15:17:17.870+0000] {subprocess.py:99} INFO - Output:
[2024-11-12T15:17:18.013+0000] {subprocess.py:106} INFO - Cannot connect to the Docker daemon at unix:///var/run/docker.sock. Is the docker daemon running?
[2024-11-12T15:17:18.015+0000] {subprocess.py:110} INFO - Command exited with return code 1
[2024-11-12T15:17:18.036+0000] {taskinstance.py:3311} ERROR - Task failed with exception
Traceback (most recent call last):
  File "/home/airflow/.local/lib/python3.12/site-packages/airflow/models/taskinstance.py", line 767, in _execute_task
    result = _execute_callable(context=context, **execute_callable_kwargs)
             ^^^^^^^^^^^^^^^^^^^^^^^^^^^^^^^^^^^^^^^^^^^^^^^^^^^^^^^^^^^^^
  File "/home/airflow/.local/lib/python3.12/site-packages/airflow/models/taskinstance.py", line 733, in _execute_callable
    return ExecutionCallableRunner(
           ^^^^^^^^^^^^^^^^^^^^^^^^
  File "/home/airflow/.local/lib/python3.12/site-packages/airflow/utils/operator_helpers.py", line 252, in run
    return self.func(*args, **kwargs)
           ^^^^^^^^^^^^^^^^^^^^^^^^^^
  File "/home/airflow/.local/lib/python3.12/site-packages/airflow/models/baseoperator.py", line 417, in wrapper
    return func(self, *args, **kwargs)
           ^^^^^^^^^^^^^^^^^^^^^^^^^^^
  File "/home/airflow/.local/lib/python3.12/site-packages/airflow/operators/bash.py", line 276, in execute
    raise AirflowException(
airflow.exceptions.AirflowException: Bash command failed. The command returned a non-zero exit code 1.
[2024-11-12T15:17:18.049+0000] {taskinstance.py:1225} INFO - Marking task as FAILED. dag_id=etl_kimdong_dag, task_id=mongodb_to_kafka, run_id=manual__2024-11-12T15:17:16.335645+00:00, execution_date=20241112T151716, start_date=20241112T151717, end_date=20241112T151718
[2024-11-12T15:17:18.078+0000] {taskinstance.py:340} INFO - ::group::Post task execution logs
[2024-11-12T15:17:18.082+0000] {standard_task_runner.py:124} ERROR - Failed to execute job 2 for task mongodb_to_kafka (Bash command failed. The command returned a non-zero exit code 1.; 200)
Traceback (most recent call last):
  File "/home/airflow/.local/lib/python3.12/site-packages/airflow/task/task_runner/standard_task_runner.py", line 117, in _start_by_fork
    ret = args.func(args, dag=self.dag)
          ^^^^^^^^^^^^^^^^^^^^^^^^^^^^^
  File "/home/airflow/.local/lib/python3.12/site-packages/airflow/cli/cli_config.py", line 49, in command
    return func(*args, **kwargs)
           ^^^^^^^^^^^^^^^^^^^^^
  File "/home/airflow/.local/lib/python3.12/site-packages/airflow/utils/cli.py", line 116, in wrapper
    return f(*args, **kwargs)
           ^^^^^^^^^^^^^^^^^^
  File "/home/airflow/.local/lib/python3.12/site-packages/airflow/cli/commands/task_command.py", line 483, in task_run
    task_return_code = _run_task_by_selected_method(args, _dag, ti)
                       ^^^^^^^^^^^^^^^^^^^^^^^^^^^^^^^^^^^^^^^^^^^^
  File "/home/airflow/.local/lib/python3.12/site-packages/airflow/cli/commands/task_command.py", line 256, in _run_task_by_selected_method
    return _run_raw_task(args, ti)
           ^^^^^^^^^^^^^^^^^^^^^^^
  File "/home/airflow/.local/lib/python3.12/site-packages/airflow/cli/commands/task_command.py", line 341, in _run_raw_task
    return ti._run_raw_task(
           ^^^^^^^^^^^^^^^^^
  File "/home/airflow/.local/lib/python3.12/site-packages/airflow/utils/session.py", line 97, in wrapper
    return func(*args, session=session, **kwargs)
           ^^^^^^^^^^^^^^^^^^^^^^^^^^^^^^^^^^^^^^
  File "/home/airflow/.local/lib/python3.12/site-packages/airflow/models/taskinstance.py", line 3005, in _run_raw_task
    return _run_raw_task(
           ^^^^^^^^^^^^^^
  File "/home/airflow/.local/lib/python3.12/site-packages/airflow/models/taskinstance.py", line 273, in _run_raw_task
    TaskInstance._execute_task_with_callbacks(
  File "/home/airflow/.local/lib/python3.12/site-packages/airflow/models/taskinstance.py", line 3159, in _execute_task_with_callbacks
    result = self._execute_task(context, task_orig)
             ^^^^^^^^^^^^^^^^^^^^^^^^^^^^^^^^^^^^^^
  File "/home/airflow/.local/lib/python3.12/site-packages/airflow/models/taskinstance.py", line 3183, in _execute_task
    return _execute_task(self, context, task_orig)
           ^^^^^^^^^^^^^^^^^^^^^^^^^^^^^^^^^^^^^^^
  File "/home/airflow/.local/lib/python3.12/site-packages/airflow/models/taskinstance.py", line 767, in _execute_task
    result = _execute_callable(context=context, **execute_callable_kwargs)
             ^^^^^^^^^^^^^^^^^^^^^^^^^^^^^^^^^^^^^^^^^^^^^^^^^^^^^^^^^^^^^
  File "/home/airflow/.local/lib/python3.12/site-packages/airflow/models/taskinstance.py", line 733, in _execute_callable
    return ExecutionCallableRunner(
           ^^^^^^^^^^^^^^^^^^^^^^^^
  File "/home/airflow/.local/lib/python3.12/site-packages/airflow/utils/operator_helpers.py", line 252, in run
    return self.func(*args, **kwargs)
           ^^^^^^^^^^^^^^^^^^^^^^^^^^
  File "/home/airflow/.local/lib/python3.12/site-packages/airflow/models/baseoperator.py", line 417, in wrapper
    return func(self, *args, **kwargs)
           ^^^^^^^^^^^^^^^^^^^^^^^^^^^
  File "/home/airflow/.local/lib/python3.12/site-packages/airflow/operators/bash.py", line 276, in execute
    raise AirflowException(
airflow.exceptions.AirflowException: Bash command failed. The command returned a non-zero exit code 1.
[2024-11-12T15:17:18.119+0000] {local_task_job_runner.py:266} INFO - Task exited with return code 1
[2024-11-12T15:17:18.142+0000] {taskinstance.py:3895} INFO - 0 downstream tasks scheduled from follow-on schedule check
[2024-11-12T15:17:18.146+0000] {local_task_job_runner.py:245} INFO - ::endgroup::
